Workbook

Sheet 1 Daily Report
A1: TEAM LEADER REPORT · FORM 1 OF 4 · KEEP ONE ROW PER WORKING DAY
A2: Daily Report
A3: Type each day in its row (blue cells). The Case Log summary, Weekly Report and Monthly Review update from this sheet.
A4: Sales columns on the right: type each agent's real profit (AED) for the day. Yellow cells need your confirmation.
A7: DATE | E7: A · CHAT QUALITY REVIEW | H7: B · COACHING, TEAM & WHITE PHONE | N7: C · TODAY'S CASES | T7: D · URGENT FOR MANAGER | U7: DAILY SALES · REAL PROFIT (AED) | AC7: TEAM
A8: Date | B8: Day | C8: Week # | D8: Working day | E8: 1 Chats reviewed | F8: 2 Chats with issues (number) | G8: Chat issue details | H8: 3 1:1 meetings held | I8: 1:1 with (agents) | J8: 4 Agents absent | K8: Absent (names) | L8: 5 White phone holder | M8: 6 Calls on white phone | N8: 7 Lost deals | O8: 8 Refunds | P8: 9 Complaints / errors | Q8: 10 Discount requests | R8: 11 System issues | S8: System issue details | T8: D · Urgent for manager | U8: ='4 Monthly Review'!B30 -> Alshima | V8: ='4 Monthly Review'!B31 -> Chaima | W8: ='4 Monthly Review'!B32 -> Harinder | X8: ='4 Monthly Review'!B33 -> Ibrahim | Y8: ='4 Monthly Review'!B34 -> Khozema | Z8: ='4 Monthly Review'!B35 -> Layan | AA8: ='4 Monthly Review'!B36 -> Rihab | AB8: ='4 Monthly Review'!B37 -> Saha | AC8: Team total | AD8: Cumulative | AE8: Date excl. Sunday (helper)
A9: =IF('4 Monthly Review'!$X$9+ROW()-9>EOMONTH('4 Monthly Review'!$X$9,0),"",'4 Monthly Review'!$X$9+ROW()-9) -> 46296 | B9: =IF(A9="","",TEXT(A9,"ddd")) -> Thu | C9: =IF(A9="","",INT((A9-WEEKDAY(A9,3)-('4 Monthly Review'!$X$9-WEEKDAY('4 Monthly Review'!$X$9,3)))/7)+1) -> 1 | D9: =IF(A9="","",IF(OR(WEEKDAY(A9,2)=7,COUNTIF('4 Monthly Review'!$B$26:$AM$26,A9)>0),0,1)) -> 1 | E9: 4 | G9: Technical issue: Instagram and TikTok leads are not counted as contact numbers; advertising leads - no potential leads. | H9: 2 | I9: Khozema, Harinder | J9: 1 | K9: Chaima | L9: Not with us today | M9: 0 | N9: 12 | O9: 0 | P9: 0 | Q9: 0 | R9: 1 | AC9: =IF(A9="","",SUM(U9:AB9)) -> 0 | AD9: =IF(A9="","",SUM($AC$9:AC9)) -> 0 | AE9: =IF(A9="","",IF(WEEKDAY(A9,2)=7,"",A9)) -> 46296
A10: =IF('4 Monthly Review'!$X$9+ROW()-9>EOMONTH('4 Monthly Review'!$X$9,0),"",'4 Monthly Review'!$X$9+ROW()-9) -> 46297 | B10: =IF(A10="","",TEXT(A10,"ddd")) -> Fri | C10: =IF(A10="","",INT((A10-WEEKDAY(A10,3)-('4 Monthly Review'!$X$9-WEEKDAY('4 Monthly Review'!$X$9,3)))/7)+1) -> 1 | D10: =IF(A10="","",IF(OR(WEEKDAY(A10,2)=7,COUNTIF('4 Monthly Review'!$B$26:$AM$26,A10)>0),0,1)) -> 1 | E10: 8 | F10: 6 | G10: Many chats redirected, mostly from Mona (already responded to earlier, then redirected to agents). On most redirected leads the agent cannot send a message - red dot appearing. | H10: 2 | I10: Khozema, Alshima | J10: 1 | K10: Rihab | L10: Ibrahim and Layan | M10: 5 | N10: 9 | O10: 0 | P10: 0 | Q10: 0 | R10: 0 | AC10: =IF(A10="","",SUM(U10:AB10)) -> 0 | AD10: =IF(A10="","",SUM($AC$9:AC10)) -> 0 | AE10: =IF(A10="","",IF(WEEKDAY(A10,2)=7,"",A10)) -> 46297
A11: =IF('4 Monthly Review'!$X$9+ROW()-9>EOMONTH('4 Monthly Review'!$X$9,0),"",'4 Monthly Review'!$X$9+ROW()-9) -> 46298 | B11: =IF(A11="","",TEXT(A11,"ddd")) -> Sat | C11: =IF(A11="","",INT((A11-WEEKDAY(A11,3)-('4 Monthly Review'!$X$9-WEEKDAY('4 Monthly Review'!$X$9,3)))/7)+1) -> 1 | D11: =IF(A11="","",IF(OR(WEEKDAY(A11,2)=7,COUNTIF('4 Monthly Review'!$B$26:$AM$26,A11)>0),0,1)) -> 1 | E11: 9 | F11: 3 | H11: 2 | I11: Khozema, Harinder | J11: 0 | L11: No | M11: 0 | N11: Most - junk leads | O11: 0 | Q11: 0 | R11: 1 | S11: CRM issue: old leads redirecting to agents. | AC11: =IF(A11="","",SUM(U11:AB11)) -> 0 | AD11: =IF(A11="","",SUM($AC$9:AC11)) -> 0 | AE11: =IF(A11="","",IF(WEEKDAY(A11,2)=7,"",A11)) -> 46298
A12: =IF('4 Monthly Review'!$X$9+ROW()-9>EOMONTH('4 Monthly Review'!$X$9,0),"",'4 Monthly Review'!$X$9+ROW()-9) -> 46299 | B12: =IF(A12="","",TEXT(A12,"ddd")) -> Sun | C12: =IF(A12="","",INT((A12-WEEKDAY(A12,3)-('4 Monthly Review'!$X$9-WEEKDAY('4 Monthly Review'!$X$9,3)))/7)+1) -> 1 | D12: =IF(A12="","",IF(OR(WEEKDAY(A12,2)=7,COUNTIF('4 Monthly Review'!$B$26:$AM$26,A12)>0),0,1)) -> 0 | AC12: =IF(A12="","",SUM(U12:AB12)) -> 0 | AD12: =IF(A12="","",SUM($AC$9:AC12)) -> 0 | AE12: =IF(A12="","",IF(WEEKDAY(A12,2)=7,"",A12))
A13: =IF('4 Monthly Review'!$X$9+ROW()-9>EOMONTH('4 Monthly Review'!$X$9,0),"",'4 Monthly Review'!$X$9+ROW()-9) -> 46300 | B13: =IF(A13="","",TEXT(A13,"ddd")) -> Mon | C13: =IF(A13="","",INT((A13-WEEKDAY(A13,3)-('4 Monthly Review'!$X$9-WEEKDAY('4 Monthly Review'!$X$9,3)))/7)+1) -> 2 | D13: =IF(A13="","",IF(OR(WEEKDAY(A13,2)=7,COUNTIF('4 Monthly Review'!$B$26:$AM$26,A13)>0),0,1)) -> 1 | AC13: =IF(A13="","",SUM(U13:AB13)) -> 0 | AD13: =IF(A13="","",SUM($AC$9:AC13)) -> 0 | AE13: =IF(A13="","",IF(WEEKDAY(A13,2)=7,"",A13)) -> 46300
A14: =IF('4 Monthly Review'!$X$9+ROW()-9>EOMONTH('4 Monthly Review'!$X$9,0),"",'4 Monthly Review'!$X$9+ROW()-9) -> 46301 | B14: =IF(A14="","",TEXT(A14,"ddd")) -> Tue | C14: =IF(A14="","",INT((A14-WEEKDAY(A14,3)-('4 Monthly Review'!$X$9-WEEKDAY('4 Monthly Review'!$X$9,3)))/7)+1) -> 2 | D14: =IF(A14="","",IF(OR(WEEKDAY(A14,2)=7,COUNTIF('4 Monthly Review'!$B$26:$AM$26,A14)>0),0,1)) -> 1 | AC14: =IF(A14="","",SUM(U14:AB14)) -> 0 | AD14: =IF(A14="","",SUM($AC$9:AC14)) -> 0 | AE14: =IF(A14="","",IF(WEEKDAY(A14,2)=7,"",A14)) -> 46301
A15: =IF('4 Monthly Review'!$X$9+ROW()-9>EOMONTH('4 Monthly Review'!$X$9,0),"",'4 Monthly Review'!$X$9+ROW()-9) -> 46302 | B15: =IF(A15="","",TEXT(A15,"ddd")) -> Wed | C15: =IF(A15="","",INT((A15-WEEKDAY(A15,3)-('4 Monthly Review'!$X$9-WEEKDAY('4 Monthly Review'!$X$9,3)))/7)+1) -> 2 | D15: =IF(A15="","",IF(OR(WEEKDAY(A15,2)=7,COUNTIF('4 Monthly Review'!$B$26:$AM$26,A15)>0),0,1)) -> 1 | AC15: =IF(A15="","",SUM(U15:AB15)) -> 0 | AD15: =IF(A15="","",SUM($AC$9:AC15)) -> 0 | AE15: =IF(A15="","",IF(WEEKDAY(A15,2)=7,"",A15)) -> 46302
A16: =IF('4 Monthly Review'!$X$9+ROW()-9>EOMONTH('4 Monthly Review'!$X$9,0),"",'4 Monthly Review'!$X$9+ROW()-9) -> 46303 | B16: =IF(A16="","",TEXT(A16,"ddd")) -> Thu | C16: =IF(A16="","",INT((A16-WEEKDAY(A16,3)-('4 Monthly Review'!$X$9-WEEKDAY('4 Monthly Review'!$X$9,3)))/7)+1) -> 2 | D16: =IF(A16="","",IF(OR(WEEKDAY(A16,2)=7,COUNTIF('4 Monthly Review'!$B$26:$AM$26,A16)>0),0,1)) -> 1 | AC16: =IF(A16="","",SUM(U16:AB16)) -> 0 | AD16: =IF(A16="","",SUM($AC$9:AC16)) -> 0 | AE16: =IF(A16="","",IF(WEEKDAY(A16,2)=7,"",A16)) -> 46303
A17: =IF('4 Monthly Review'!$X$9+ROW()-9>EOMONTH('4 Monthly Review'!$X$9,0),"",'4 Monthly Review'!$X$9+ROW()-9) -> 46304 | B17: =IF(A17="","",TEXT(A17,"ddd")) -> Fri | C17: =IF(A17="","",INT((A17-WEEKDAY(A17,3)-('4 Monthly Review'!$X$9-WEEKDAY('4 Monthly Review'!$X$9,3)))/7)+1) -> 2 | D17: =IF(A17="","",IF(OR(WEEKDAY(A17,2)=7,COUNTIF('4 Monthly Review'!$B$26:$AM$26,A17)>0),0,1)) -> 1 | AC17: =IF(A17="","",SUM(U17:AB17)) -> 0 | AD17: =IF(A17="","",SUM($AC$9:AC17)) -> 0 | AE17: =IF(A17="","",IF(WEEKDAY(A17,2)=7,"",A17)) -> 46304
A18: =IF('4 Monthly Review'!$X$9+ROW()-9>EOMONTH('4 Monthly Review'!$X$9,0),"",'4 Monthly Review'!$X$9+ROW()-9) -> 46305 | B18: =IF(A18="","",TEXT(A18,"ddd")) -> Sat | C18: =IF(A18="","",INT((A18-WEEKDAY(A18,3)-('4 Monthly Review'!$X$9-WEEKDAY('4 Monthly Review'!$X$9,3)))/7)+1) -> 2 | D18: =IF(A18="","",IF(OR(WEEKDAY(A18,2)=7,COUNTIF('4 Monthly Review'!$B$26:$AM$26,A18)>0),0,1)) -> 1 | AC18: =IF(A18="","",SUM(U18:AB18)) -> 0 | AD18: =IF(A18="","",SUM($AC$9:AC18)) -> 0 | AE18: =IF(A18="","",IF(WEEKDAY(A18,2)=7,"",A18)) -> 46305
A19: =IF('4 Monthly Review'!$X$9+ROW()-9>EOMONTH('4 Monthly Review'!$X$9,0),"",'4 Monthly Review'!$X$9+ROW()-9) -> 46306 | B19: =IF(A19="","",TEXT(A19,"ddd")) -> Sun | C19: =IF(A19="","",INT((A19-WEEKDAY(A19,3)-('4 Monthly Review'!$X$9-WEEKDAY('4 Monthly Review'!$X$9,3)))/7)+1) -> 2 | D19: =IF(A19="","",IF(OR(WEEKDAY(A19,2)=7,COUNTIF('4 Monthly Review'!$B$26:$AM$26,A19)>0),0,1)) -> 0 | AC19: =IF(A19="","",SUM(U19:AB19)) -> 0 | AD19: =IF(A19="","",SUM($AC$9:AC19)) -> 0 | AE19: =IF(A19="","",IF(WEEKDAY(A19,2)=7,"",A19))
A20: =IF('4 Monthly Review'!$X$9+ROW()-9>EOMONTH('4 Monthly Review'!$X$9,0),"",'4 Monthly Review'!$X$9+ROW()-9) -> 46307 | B20: =IF(A20="","",TEXT(A20,"ddd")) -> Mon | C20: =IF(A20="","",INT((A20-WEEKDAY(A20,3)-('4 Monthly Review'!$X$9-WEEKDAY('4 Monthly Review'!$X$9,3)))/7)+1) -> 3 | D20: =IF(A20="","",IF(OR(WEEKDAY(A20,2)=7,COUNTIF('4 Monthly Review'!$B$26:$AM$26,A20)>0),0,1)) -> 1 | AC20: =IF(A20="","",SUM(U20:AB20)) -> 0 | AD20: =IF(A20="","",SUM($AC$9:AC20)) -> 0 | AE20: =IF(A20="","",IF(WEEKDAY(A20,2)=7,"",A20)) -> 46307
A21: =IF('4 Monthly Review'!$X$9+ROW()-9>EOMONTH('4 Monthly Review'!$X$9,0),"",'4 Monthly Review'!$X$9+ROW()-9) -> 46308 | B21: =IF(A21="","",TEXT(A21,"ddd")) -> Tue | C21: =IF(A21="","",INT((A21-WEEKDAY(A21,3)-('4 Monthly Review'!$X$9-WEEKDAY('4 Monthly Review'!$X$9,3)))/7)+1) -> 3 | D21: =IF(A21="","",IF(OR(WEEKDAY(A21,2)=7,COUNTIF('4 Monthly Review'!$B$26:$AM$26,A21)>0),0,1)) -> 1 | AC21: =IF(A21="","",SUM(U21:AB21)) -> 0 | AD21: =IF(A21="","",SUM($AC$9:AC21)) -> 0 | AE21: =IF(A21="","",IF(WEEKDAY(A21,2)=7,"",A21)) -> 46308
A22: =IF('4 Monthly Review'!$X$9+ROW()-9>EOMONTH('4 Monthly Review'!$X$9,0),"",'4 Monthly Review'!$X$9+ROW()-9) -> 46309 | B22: =IF(A22="","",TEXT(A22,"ddd")) -> Wed | C22: =IF(A22="","",INT((A22-WEEKDAY(A22,3)-('4 Monthly Review'!$X$9-WEEKDAY('4 Monthly Review'!$X$9,3)))/7)+1) -> 3 | D22: =IF(A22="","",IF(OR(WEEKDAY(A22,2)=7,COUNTIF('4 Monthly Review'!$B$26:$AM$26,A22)>0),0,1)) -> 1 | AC22: =IF(A22="","",SUM(U22:AB22)) -> 0 | AD22: =IF(A22="","",SUM($AC$9:AC22)) -> 0 | AE22: =IF(A22="","",IF(WEEKDAY(A22,2)=7,"",A22)) -> 46309
A23: =IF('4 Monthly Review'!$X$9+ROW()-9>EOMONTH('4 Monthly Review'!$X$9,0),"",'4 Monthly Review'!$X$9+ROW()-9) -> 46310 | B23: =IF(A23="","",TEXT(A23,"ddd")) -> Thu | C23: =IF(A23="","",INT((A23-WEEKDAY(A23,3)-('4 Monthly Review'!$X$9-WEEKDAY('4 Monthly Review'!$X$9,3)))/7)+1) -> 3 | D23: =IF(A23="","",IF(OR(WEEKDAY(A23,2)=7,COUNTIF('4 Monthly Review'!$B$26:$AM$26,A23)>0),0,1)) -> 1 | AC23: =IF(A23="","",SUM(U23:AB23)) -> 0 | AD23: =IF(A23="","",SUM($AC$9:AC23)) -> 0 | AE23: =IF(A23="","",IF(WEEKDAY(A23,2)=7,"",A23)) -> 46310
... A39: =IF('4 Monthly Review'!$X$9+ROW()-9>EOMONTH('4 Monthly Review'!$X$9,0),"",'4 Monthly Review'!$X$9+ROW()-9) -> 46326 | B39: =IF(A39="","",TEXT(A39,"ddd")) -> Sat | C39: =IF(A39="","",INT((A39-WEEKDAY(A39,3)-('4 Monthly Review'!$X$9-WEEKDAY('4 Monthly Review'!$X$9,3)))/7)+1) -> 5 | D39: =IF(A39="","",IF(OR(WEEKDAY(A39,2)=7,COUNTIF('4 Monthly Review'!$B$26:$AM$26,A39)>0),0,1)) -> 1 | AC39: =IF(A39="","",SUM(U39:AB39)) -> 0 | AD39: =IF(A39="","",SUM($AC$9:AC39)) -> 0 | AE39: =IF(A39="","",IF(WEEKDAY(A39,2)=7,"",A39)) -> 46326
A40: TOTAL | E40: =SUM(E9:E39) -> 21 | F40: =SUM(F9:F39) -> 9 | H40: =SUM(H9:H39) -> 6 | J40: =SUM(J9:J39) -> 2 | M40: =SUM(M9:M39) -> 5 | N40: =SUM(N9:N39) -> 21 | O40: =SUM(O9:O39) -> 0 | P40: =SUM(P9:P39) -> 0 | Q40: =SUM(Q9:Q39) -> 0 | R40: =SUM(R9:R39) -> 2 | U40: =SUM(U9:U39) -> 0 | V40: =SUM(V9:V39) -> 0 | W40: =SUM(W9:W39) -> 0 | X40: =SUM(X9:X39) -> 0 | Y40: =SUM(Y9:Y39) -> 0 | Z40: =SUM(Z9:Z39) -> 0 | AA40: =SUM(AA9:AA39) -> 0 | AB40: =SUM(AB9:AB39) -> 0 | AC40: =SUM(AC9:AC39) -> 0

Sheet 2 Case Log
C2: TEAM LEADER REPORT · FORM 2 OF 4 | AU2: FORM 2
C3: Case Log | AR3: As it happens · weekly summary
C4: One row per item, logged on the day it happens · all logs for the month are kept on this sheet
B8: TEAM LEADER NAME | U8: TEAM | AG8: WEEK FROM | AS8: WEEK TO
B9: ='4 Monthly Review'!$B$9 -> Bindhya TB | U9: ='4 Monthly Review'!$O$9 -> Tourism & Business | AG9: =IFERROR(INDEX('4 Monthly Review'!$F$18:$F$22,'3 Weekly Report'!$H$2),"") -> 46296 | AS9: =IFERROR(INDEX('4 Monthly Review'!$K$18:$K$22,'3 Weekly Report'!$H$2),"") -> 46298
B11: ="Showing WEEK "&'3 Weekly Report'!$H$2&" in the Weekly Summary below. Change the week on sheet 3 (Weekly Report). Logs further down hold the whole month." -> Showing WEEK 1 in the Weekly Summary below. Change the week on sheet 3 (Weekly Report). Logs further down hold the whole month.
C13: WEEKLY SUMMARY | AF13: Count each log at the end of the week · submit with Form 3 · Weekly Report
C14: CHATS WITH ISSUES | Q14: 1:1 MEETINGS | AE14: LOST DEALS | AS14: REFUNDS
C15: Number | Q15: Number | AE15: Number | AS15: Number | AY15: Total AED
C16: =IFERROR(SUMIFS('1 Daily Report'!$F$9:$F$39,'1 Daily Report'!$A$9:$A$39,">="&INDEX('4 Monthly Review'!$F$18:$F$22,'3 Weekly Report'!$H$2),'1 Daily Report'!$A$9:$A$39,"<="&INDEX('4 Monthly Review'!$K$18:$K$22,'3 Weekly Report'!$H$2)),0) -> 9 | Q16: =IFERROR(SUMIFS('1 Daily Report'!$H$9:$H$39,'1 Daily Report'!$A$9:$A$39,">="&INDEX('4 Monthly Review'!$F$18:$F$22,'3 Weekly Report'!$H$2),'1 Daily Report'!$A$9:$A$39,"<="&INDEX('4 Monthly Review'!$K$18:$K$22,'3 Weekly Report'!$H$2)),0) -> 6 | AE16: =IFERROR(SUMIFS('1 Daily Report'!$N$9:$N$39,'1 Daily Report'!$A$9:$A$39,">="&INDEX('4 Monthly Review'!$F$18:$F$22,'3 Weekly Report'!$H$2),'1 Daily Report'!$A$9:$A$39,"<="&INDEX('4 Monthly Review'!$K$18:$K$22,'3 Weekly Report'!$H$2)),0) -> 21 | AS16: =IFERROR(SUMIFS('1 Daily Report'!$O$9:$O$39,'1 Daily Report'!$A$9:$A$39,">="&INDEX('4 Monthly Review'!$F$18:$F$22,'3 Weekly Report'!$H$2),'1 Daily Report'!$A$9:$A$39,"<="&INDEX('4 Monthly Review'!$K$18:$K$22,'3 Weekly Report'!$H$2)),0) -> 0 | AY16: =IFERROR(SUMIFS($W$472:$W$511,$D$472:$D$511,">="&INDEX('4 Monthly Review'!$F$18:$F$22,'3 Weekly Report'!$H$2),$D$472:$D$511,"<="&INDEX('4 Monthly Review'!$K$18:$K$22,'3 Weekly Report'!$H$2)),0) -> 0
C19: COMPLAINTS / ERRORS | Q19: DISCOUNT REQUESTS | AE19: SYSTEM ISSUES | AS19: WHITE PHONE CALLS
C20: Number | I20: Still open | Q20: Number | W20: Approved | AE20: Number | AK20: Still open | AS20: Number
C21: =IFERROR(SUMIFS('1 Daily Report'!$P$9:$P$39,'1 Daily Report'!$A$9:$A$39,">="&INDEX('4 Monthly Review'!$F$18:$F$22,'3 Weekly Report'!$H$2),'1 Daily Report'!$A$9:$A$39,"<="&INDEX('4 Monthly Review'!$K$18:$K$22,'3 Weekly Report'!$H$2)),0) -> 0 | I21: =IFERROR(COUNTIFS($AW$516:$AW$555,"O",$D$516:$D$555,">="&INDEX('4 Monthly Review'!$F$18:$F$22,'3 Weekly Report'!$H$2),$D$516:$D$555,"<="&INDEX('4 Monthly Review'!$K$18:$K$22,'3 Weekly Report'!$H$2)),0) -> 0 | Q21: =IFERROR(SUMIFS('1 Daily Report'!$Q$9:$Q$39,'1 Daily Report'!$A$9:$A$39,">="&INDEX('4 Monthly Review'!$F$18:$F$22,'3 Weekly Report'!$H$2),'1 Daily Report'!$A$9:$A$39,"<="&INDEX('4 Monthly Review'!$K$18:$K$22,'3 Weekly Report'!$H$2)),0) -> 0 | W21: =IFERROR(COUNTIFS($AC$560:$AC$599,">0",$D$560:$D$599,">="&INDEX('4 Monthly Review'!$F$18:$F$22,'3 Weekly Report'!$H$2),$D$560:$D$599,"<="&INDEX('4 Monthly Review'!$K$18:$K$22,'3 Weekly Report'!$H$2)),0) -> 0 | AE21: =IFERROR(SUMIFS('1 Daily Report'!$R$9:$R$39,'1 Daily Report'!$A$9:$A$39,">="&INDEX('4 Monthly Review'!$F$18:$F$22,'3 Weekly Report'!$H$2),'1 Daily Report'!$A$9:$A$39,"<="&INDEX('4 Monthly Review'!$K$18:$K$22,'3 Weekly Report'!$H$2)),0) -> 2 | AK21: =IFERROR(COUNTIFS($AV$604:$AV$643,"O",$D$604:$D$643,">="&INDEX('4 Monthly Review'!$F$18:$F$22,'3 Weekly Report'!$H$2),$D$604:$D$643,"<="&INDEX('4 Monthly Review'!$K$18:$K$22,'3 Weekly Report'!$H$2)),0) -> 0 | AS21: =IFERROR(SUMIFS('1 Daily Report'!$M$9:$M$39,'1 Daily Report'!$A$9:$A$39,">="&INDEX('4 Monthly Review'!$F$18:$F$22,'3 Weekly Report'!$H$2),'1 Daily Report'!$A$9:$A$39,"<="&INDEX('4 Monthly Review'!$K$18:$K$22,'3 Weekly Report'!$H$2)),0) -> 5
C24: How to use: log each item on the day it happens · one row per item · write the code from the key under each table · the Weekly Summary above fills from the Daily Report and these logs · submit with Form 3 · Weekly Report.
C28: CHAT REVIEW ISSUES | AL28: One row per chat with an issue · from the daily chat review
B29: # | D29: CHAT DATE | H29: AGENT | O29: CLIENT NAME / DEAL ID | V29: ISSUE CODE | Z29: FEEDBACK GIVEN TO THE AGENT
B30: 1 | D30: 46296 | Z30: Technical issue: Instagram and TikTok leads not counted as contact numbers; advertising leads - no potential leads.
B31: 2 | D31: 46297 | Z31: Many chats redirected, mostly from Mona (already responded to earlier, then redirected to agents). On most redirected leads the agent cannot send a message - red dot appearing.
B32: 3
B33: 4
B34: 5
B35: 6
B36: 7
B37: 8
B38: 9
B39: 10
B40: 11
B41: 12
B42: 13
B43: 14
... B129: 100
B130: KEY | E130: Issue codes: GT Greeting / tone · QL Qualification · PI Product info wrong · PQ Price / quotation error · OH Objection handling · NC No closing attempt · SR Slow response · NF No follow-up set · GC Grammar / clarity · PB Policy breach · OT Other
C132: LOG 1 · ONE-TO-ONE (1:1) MEETINGS | AL132: One row per meeting
B133: # | D133: DATE | H133: AGENT | P133: TOPIC | T133: KEY POINTS DISCUSSED | AN133: ACTION AGREED
B134: 1 | D134: 46296 | H134: Khozema
B135: 2 | D135: 46296 | H135: Harinder
B136: 3 | D136: 46297 | H136: Khozema
B137: 4 | D137: 46297 | H137: Alshima
B138: 5 | D138: 46298 | H138: Khozema
B139: 6 | D139: 46298 | H139: Harinder
...

Sheet 3 Weekly Report
C2: SELECT WEEK | H2: 1 | L2: ="Week "&$H$2&": "&TEXT(IFERROR(INDEX('4 Monthly Review'!$F$18:$F$22,$H$2),""),"dd mmm yyyy")&" to "&TEXT(IFERROR(INDEX('4 Monthly Review'!$K$18:$K$22,$H$2),""),"dd mmm yyyy") -> Week 1: 01 Oct 2026 to 03 Oct 2026
C5: TEAM LEADER REPORT · FORM 3 OF 4 | AE5: FORM 3
C6: Weekly Report | AB6: Every week
C7: Filled on the last working day of each week (Saturday)
B11: TEAM LEADER NAME | O11: TEAM | X11: WEEK FROM | AG11: WEEK TO
B12: ='4 Monthly Review'!$B$9 -> Bindhya TB | O12: ='4 Monthly Review'!$O$9 -> Tourism & Business | X12: =IFERROR(INDEX('4 Monthly Review'!$F$18:$F$22,$H$2),"") -> 46296 | AG12: =IFERROR(INDEX('4 Monthly Review'!$K$18:$K$22,$H$2),"") -> 46298
C14: A · TEAM TARGET
C15: 1 | D15: WEEKLY TARGET | P15: 2 | Q15: ACHIEVED THIS WEEK | AC15: 3 | AD15: ACHIEVEMENT
C16: =IF(OR('4 Monthly Review'!$AF$9="",SUMIFS('1 Daily Report'!$D$9:$D$39,'1 Daily Report'!$C$9:$C$39,">0")=0),"",'4 Monthly Review'!$AF$9/SUMIFS('1 Daily Report'!$D$9:$D$39,'1 Daily Report'!$C$9:$C$39,">0")*INDEX('4 Monthly Review'!$P$18:$P$22,$H$2)) | P16: =IFERROR(SUMIFS('1 Daily Report'!$AC$9:$AC$39,'1 Daily Report'!$A$9:$A$39,">="&INDEX('4 Monthly Review'!$F$18:$F$22,$H$2),'1 Daily Report'!$A$9:$A$39,"<="&INDEX('4 Monthly Review'!$K$18:$K$22,$H$2)),0) -> 0 | AC16: =IF(OR(C16="",N(P16)=0),"",P16/C16)
C19: B · AGENT TARGETS
B20: # | D20: AGENT | R20: WEEKLY TARGET (AED) | Z20: ACHIEVED (AED) | AH20: ACHIEVEMENT %
B21: 1 | D21: ='4 Monthly Review'!$B$30 -> Alshima | R21: =IF(OR('4 Monthly Review'!$H$30="",SUMIFS('1 Daily Report'!$D$9:$D$39,'1 Daily Report'!$C$9:$C$39,">0")=0),"",'4 Monthly Review'!$H$30/SUMIFS('1 Daily Report'!$D$9:$D$39,'1 Daily Report'!$C$9:$C$39,">0")*INDEX('4 Monthly Review'!$P$18:$P$22,$H$2)) | Z21: =SUMPRODUCT(('1 Daily Report'!$U$8:$AB$8=$D21)*('1 Daily Report'!$A$9:$A$39>=INDEX('4 Monthly Review'!$F$18:$F$22,$H$2))*('1 Daily Report'!$A$9:$A$39<=INDEX('4 Monthly Review'!$K$18:$K$22,$H$2))*'1 Daily Report'!$U$9:$AB$39) -> 0 | AH21: =IF(OR(R21="",N(Z21)=0),"",Z21/R21)
B22: 2 | D22: ='4 Monthly Review'!$B$31 -> Chaima | R22: =IF(OR('4 Monthly Review'!$H$31="",SUMIFS('1 Daily Report'!$D$9:$D$39,'1 Daily Report'!$C$9:$C$39,">0")=0),"",'4 Monthly Review'!$H$31/SUMIFS('1 Daily Report'!$D$9:$D$39,'1 Daily Report'!$C$9:$C$39,">0")*INDEX('4 Monthly Review'!$P$18:$P$22,$H$2)) | Z22: =SUMPRODUCT(('1 Daily Report'!$U$8:$AB$8=$D22)*('1 Daily Report'!$A$9:$A$39>=INDEX('4 Monthly Review'!$F$18:$F$22,$H$2))*('1 Daily Report'!$A$9:$A$39<=INDEX('4 Monthly Review'!$K$18:$K$22,$H$2))*'1 Daily Report'!$U$9:$AB$39) -> 0 | AH22: =IF(OR(R22="",N(Z22)=0),"",Z22/R22)
B23: 3 | D23: ='4 Monthly Review'!$B$32 -> Harinder | R23: =IF(OR('4 Monthly Review'!$H$32="",SUMIFS('1 Daily Report'!$D$9:$D$39,'1 Daily Report'!$C$9:$C$39,">0")=0),"",'4 Monthly Review'!$H$32/SUMIFS('1 Daily Report'!$D$9:$D$39,'1 Daily Report'!$C$9:$C$39,">0")*INDEX('4 Monthly Review'!$P$18:$P$22,$H$2)) | Z23: =SUMPRODUCT(('1 Daily Report'!$U$8:$AB$8=$D23)*('1 Daily Report'!$A$9:$A$39>=INDEX('4 Monthly Review'!$F$18:$F$22,$H$2))*('1 Daily Report'!$A$9:$A$39<=INDEX('4 Monthly Review'!$K$18:$K$22,$H$2))*'1 Daily Report'!$U$9:$AB$39) -> 0 | AH23: =IF(OR(R23="",N(Z23)=0),"",Z23/R23)
B24: 4 | D24: ='4 Monthly Review'!$B$33 -> Ibrahim | R24: =IF(OR('4 Monthly Review'!$H$33="",SUMIFS('1 Daily Report'!$D$9:$D$39,'1 Daily Report'!$C$9:$C$39,">0")=0),"",'4 Monthly Review'!$H$33/SUMIFS('1 Daily Report'!$D$9:$D$39,'1 Daily Report'!$C$9:$C$39,">0")*INDEX('4 Monthly Review'!$P$18:$P$22,$H$2)) | Z24: =SUMPRODUCT(('1 Daily Report'!$U$8:$AB$8=$D24)*('1 Daily Report'!$A$9:$A$39>=INDEX('4 Monthly Review'!$F$18:$F$22,$H$2))*('1 Daily Report'!$A$9:$A$39<=INDEX('4 Monthly Review'!$K$18:$K$22,$H$2))*'1 Daily Report'!$U$9:$AB$39) -> 0 | AH24: =IF(OR(R24="",N(Z24)=0),"",Z24/R24)
B25: 5 | D25: ='4 Monthly Review'!$B$34 -> Khozema | R25: =IF(OR('4 Monthly Review'!$H$34="",SUMIFS('1 Daily Report'!$D$9:$D$39,'1 Daily Report'!$C$9:$C$39,">0")=0),"",'4 Monthly Review'!$H$34/SUMIFS('1 Daily Report'!$D$9:$D$39,'1 Daily Report'!$C$9:$C$39,">0")*INDEX('4 Monthly Review'!$P$18:$P$22,$H$2)) | Z25: =SUMPRODUCT(('1 Daily Report'!$U$8:$AB$8=$D25)*('1 Daily Report'!$A$9:$A$39>=INDEX('4 Monthly Review'!$F$18:$F$22,$H$2))*('1 Daily Report'!$A$9:$A$39<=INDEX('4 Monthly Review'!$K$18:$K$22,$H$2))*'1 Daily Report'!$U$9:$AB$39) -> 0 | AH25: =IF(OR(R25="",N(Z25)=0),"",Z25/R25)
B26: 6 | D26: ='4 Monthly Review'!$B$35 -> Layan | R26: =IF(OR('4 Monthly Review'!$H$35="",SUMIFS('1 Daily Report'!$D$9:$D$39,'1 Daily Report'!$C$9:$C$39,">0")=0),"",'4 Monthly Review'!$H$35/SUMIFS('1 Daily Report'!$D$9:$D$39,'1 Daily Report'!$C$9:$C$39,">0")*INDEX('4 Monthly Review'!$P$18:$P$22,$H$2)) | Z26: =SUMPRODUCT(('1 Daily Report'!$U$8:$AB$8=$D26)*('1 Daily Report'!$A$9:$A$39>=INDEX('4 Monthly Review'!$F$18:$F$22,$H$2))*('1 Daily Report'!$A$9:$A$39<=INDEX('4 Monthly Review'!$K$18:$K$22,$H$2))*'1 Daily Report'!$U$9:$AB$39) -> 0 | AH26: =IF(OR(R26="",N(Z26)=0),"",Z26/R26)
B27: 7 | D27: ='4 Monthly Review'!$B$36 -> Rihab | R27: =IF(OR('4 Monthly Review'!$H$36="",SUMIFS('1 Daily Report'!$D$9:$D$39,'1 Daily Report'!$C$9:$C$39,">0")=0),"",'4 Monthly Review'!$H$36/SUMIFS('1 Daily Report'!$D$9:$D$39,'1 Daily Report'!$C$9:$C$39,">0")*INDEX('4 Monthly Review'!$P$18:$P$22,$H$2)) | Z27: =SUMPRODUCT(('1 Daily Report'!$U$8:$AB$8=$D27)*('1 Daily Report'!$A$9:$A$39>=INDEX('4 Monthly Review'!$F$18:$F$22,$H$2))*('1 Daily Report'!$A$9:$A$39<=INDEX('4 Monthly Review'!$K$18:$K$22,$H$2))*'1 Daily Report'!$U$9:$AB$39) -> 0 | AH27: =IF(OR(R27="",N(Z27)=0),"",Z27/R27)
B28: 8 | D28: ='4 Monthly Review'!$B$37 -> Saha | R28: =IF(OR('4 Monthly Review'!$H$37="",SUMIFS('1 Daily Report'!$D$9:$D$39,'1 Daily Report'!$C$9:$C$39,">0")=0),"",'4 Monthly Review'!$H$37/SUMIFS('1 Daily Report'!$D$9:$D$39,'1 Daily Report'!$C$9:$C$39,">0")*INDEX('4 Monthly Review'!$P$18:$P$22,$H$2)) | Z28: =SUMPRODUCT(('1 Daily Report'!$U$8:$AB$8=$D28)*('1 Daily Report'!$A$9:$A$39>=INDEX('4 Monthly Review'!$F$18:$F$22,$H$2))*('1 Daily Report'!$A$9:$A$39<=INDEX('4 Monthly Review'!$K$18:$K$22,$H$2))*'1 Daily Report'!$U$9:$AB$39) -> 0 | AH28: =IF(OR(R28="",N(Z28)=0),"",Z28/R28)
B29: 9
C31: C · PENDING CASES | J31: Details in Form 2 · Log 8 | T31: D · GREY LEADS | Z31: Leads from around 60–90 days ago
C32: 4 | D32: OPEN NOW | L32: 5 | M32: EXPECTED TO BOOK NEXT WEEK | T32: 6 | U32: CONTACTED | AB32: 7 | AC32: REPLIED | AI32: 8 | AJ32: CONVERTED TO SALE
C33: =IFERROR(COUNTIFS('2 Case Log'!$AZ$692:$AZ$751,$H$2,'2 Case Log'!$D$692:$D$751,"<>"),0) -> 0 | L33: =IFERROR(COUNTIFS('2 Case Log'!$AZ$692:$AZ$751,$H$2,'2 Case Log'!$AR$692:$AR$751,">"&INDEX('4 Monthly Review'!$K$18:$K$22,$H$2),'2 Case Log'!$AR$692:$AR$751,"<="&(INDEX('4 Monthly Review'!$K$18:$K$22,$H$2)+7)),0) -> 0 | T33: =IF(CHOOSE($H$2,J92,P92,V92,AB92,AH92)="","",CHOOSE($H$2,J92,P92,V92,AB92,AH92)) | AB33: =IF(CHOOSE($H$2,J93,P93,V93,AB93,AH93)="","",CHOOSE($H$2,J93,P93,V93,AB93,AH93)) | AI33: =IF(CHOOSE($H$2,J94,P94,V94,AB94,AH94)="","",CHOOSE($H$2,J94,P94,V94,AB94,AH94))
C36: E · TOP 3 ACTIONS FOR NEXT WEEK
B37: 1 | C37: =IF(CHOOSE($H$2,J95,P95,V95,AB95,AH95)="","",CHOOSE($H$2,J95,P95,V95,AB95,AH95))
B38: 2 | C38: =IF(CHOOSE($H$2,J96,P96,V96,AB96,AH96)="","",CHOOSE($H$2,J96,P96,V96,AB96,AH96))
B39: 3 | C39: =IF(CHOOSE($H$2,J97,P97,V97,AB97,AH97)="","",CHOOSE($H$2,J97,P97,V97,AB97,AH97))
C41: Submit with this form: this week's Form 2 · Case Log (all logs and the Weekly Summary filled in).
B44: TEAM LEADER SIGNATURE | L44: Date: ___________ | U44: REVIEWED BY MANAGER | AF44: Date: ___________
B46: Form 3 · Weekly Report · Team Leader Report Forms | T46: Page 1 of 1
B88: WEEKLY INPUTS · type grey leads and the top 3 actions for each week here (blue). The report above shows the selected week.
B90: ITEM | J90: Week 1 | P90: Week 2 | V90: Week 3 | AB90: Week 4 | AH90: Week 5
B91: 6 Grey leads contacted
B92: 7 Grey leads replied
B93: 8 Converted to sale
B94: Top action 1
B95: Top action 2
B96: Top action 3

Sheet 4 Monthly Review
C2: TEAM LEADER REPORT · FORM 4 OF 4 | AE2: FORM 4
C3: Monthly Agent Review | AB3: Monthly · one per agent
C4: Month dashboard first, then one review per agent (choose the agent below) · includes the Agent Skill Card
B8: TEAM LEADER NAME | O8: TEAM | X8: MONTH START (1ST DAY) | AF8: TEAM TARGET THIS MONTH (AED)
B9: Bindhya TB | O9: Tourism & Business | X9: 46296
C11: MONTH DASHBOARD
B12: TEAM TARGET | I12: ACHIEVED | P12: ACHIEVEMENT | W12: REMAINING | AC12: REQUIRED PER WORKING DAY | AI12: FORECAST AT CURRENT PACE
B13: =IF('4 Monthly Review'!$AF$9="","",'4 Monthly Review'!$AF$9) | I13: =SUM('1 Daily Report'!$AC$9:$AC$39) -> 0 | P13: =IF('4 Monthly Review'!$AF$9="","",SUM('1 Daily Report'!$AC$9:$AC$39)/'4 Monthly Review'!$AF$9) | W13: =IF('4 Monthly Review'!$AF$9="","",MAX(0,'4 Monthly Review'!$AF$9-SUM('1 Daily Report'!$AC$9:$AC$39))) | AC13: =IF(OR('4 Monthly Review'!$AF$9="",SUMIFS('1 Daily Report'!$D$9:$D$39,'1 Daily Report'!$C$9:$C$39,">0")-SUMIFS('1 Daily Report'!$D$9:$D$39,'1 Daily Report'!$A$9:$A$39,"<="&TODAY())<=0),"",MAX(0,'4 Monthly Review'!$AF$9-SUM('1 Daily Report'!$AC$9:$AC$39))/(SUMIFS('1 Daily Report'!$D$9:$D$39,'1 Daily Report'!$C$9:$C$39,">0")-SUMIFS('1 Daily Report'!$D$9:$D$39,'1 Daily Report'!$A$9:$A$39,"<="&TODAY()))) | AI13: =IF(SUMIFS('1 Daily Report'!$D$9:$D$39,'1 Daily Report'!$A$9:$A$39,"<="&TODAY())=0,"",SUM('1 Daily Report'!$AC$9:$AC$39)/SUMIFS('1 Daily Report'!$D$9:$D$39,'1 Daily Report'!$A$9:$A$39,"<="&TODAY())*SUMIFS('1 Daily Report'!$D$9:$D$39,'1 Daily Report'!$C$9:$C$39,">0")) -> 0
B14: AED | I14: AED | P14: of target | W14: AED | AC14: AED per day to hit target | AI14: AED at month-end
C16: WEEKS (Monday to Saturday) AND WORKING DAYS
B17: WEEK | F17: FROM | K17: TO | P17: WORKING DAYS | U17: TARGET (AED) | AA17: ACHIEVED (AED) | AG17: ACHIEVEMENT %
B18: Week 1 | F18: =IF(COUNTIF('1 Daily Report'!$C$9:$C$39,1)=0,"",_xlfn.MINIFS('1 Daily Report'!$AE$9:$AE$39,'1 Daily Report'!$C$9:$C$39,1)) -> 46296 | K18: =IF(COUNTIF('1 Daily Report'!$C$9:$C$39,1)=0,"",_xlfn.MAXIFS('1 Daily Report'!$AE$9:$AE$39,'1 Daily Report'!$C$9:$C$39,1)) -> 46298 | P18: =SUMIFS('1 Daily Report'!$D$9:$D$39,'1 Daily Report'!$C$9:$C$39,1) -> 3 | U18: =IF(OR('4 Monthly Review'!$AF$9="",SUMIFS('1 Daily Report'!$D$9:$D$39,'1 Daily Report'!$C$9:$C$39,">0")=0),"",'4 Monthly Review'!$AF$9/SUMIFS('1 Daily Report'!$D$9:$D$39,'1 Daily Report'!$C$9:$C$39,">0")*P18) | AA18: =IF(F18="","",SUMIFS('1 Daily Report'!$AC$9:$AC$39,'1 Daily Report'!$A$9:$A$39,">="&F18,'1 Daily Report'!$A$9:$A$39,"<="&K18)) -> 0 | AG18: =IF(OR(U18="",AA18=""),"",AA18/U18)
B19: Week 2 | F19: =IF(COUNTIF('1 Daily Report'!$C$9:$C$39,2)=0,"",_xlfn.MINIFS('1 Daily Report'!$AE$9:$AE$39,'1 Daily Report'!$C$9:$C$39,2)) -> 46300 | K19: =IF(COUNTIF('1 Daily Report'!$C$9:$C$39,2)=0,"",_xlfn.MAXIFS('1 Daily Report'!$AE$9:$AE$39,'1 Daily Report'!$C$9:$C$39,2)) -> 46305 | P19: =SUMIFS('1 Daily Report'!$D$9:$D$39,'1 Daily Report'!$C$9:$C$39,2) -> 6 | U19: =IF(OR('4 Monthly Review'!$AF$9="",SUMIFS('1 Daily Report'!$D$9:$D$39,'1 Daily Report'!$C$9:$C$39,">0")=0),"",'4 Monthly Review'!$AF$9/SUMIFS('1 Daily Report'!$D$9:$D$39,'1 Daily Report'!$C$9:$C$39,">0")*P19) | AA19: =IF(F19="","",SUMIFS('1 Daily Report'!$AC$9:$AC$39,'1 Daily Report'!$A$9:$A$39,">="&F19,'1 Daily Report'!$A$9:$A$39,"<="&K19)) -> 0 | AG19: =IF(OR(U19="",AA19=""),"",AA19/U19)
B20: Week 3 | F20: =IF(COUNTIF('1 Daily Report'!$C$9:$C$39,3)=0,"",_xlfn.MINIFS('1 Daily Report'!$AE$9:$AE$39,'1 Daily Report'!$C$9:$C$39,3)) -> 46307 | K20: =IF(COUNTIF('1 Daily Report'!$C$9:$C$39,3)=0,"",_xlfn.MAXIFS('1 Daily Report'!$AE$9:$AE$39,'1 Daily Report'!$C$9:$C$39,3)) -> 46312 | P20: =SUMIFS('1 Daily Report'!$D$9:$D$39,'1 Daily Report'!$C$9:$C$39,3) -> 6 | U20: =IF(OR('4 Monthly Review'!$AF$9="",SUMIFS('1 Daily Report'!$D$9:$D$39,'1 Daily Report'!$C$9:$C$39,">0")=0),"",'4 Monthly Review'!$AF$9/SUMIFS('1 Daily Report'!$D$9:$D$39,'1 Daily Report'!$C$9:$C$39,">0")*P20) | AA20: =IF(F20="","",SUMIFS('1 Daily Report'!$AC$9:$AC$39,'1 Daily Report'!$A$9:$A$39,">="&F20,'1 Daily Report'!$A$9:$A$39,"<="&K20)) -> 0 | AG20: =IF(OR(U20="",AA20=""),"",AA20/U20)
B21: Week 4 | F21: =IF(COUNTIF('1 Daily Report'!$C$9:$C$39,4)=0,"",_xlfn.MINIFS('1 Daily Report'!$AE$9:$AE$39,'1 Daily Report'!$C$9:$C$39,4)) -> 46314 | K21: =IF(COUNTIF('1 Daily Report'!$C$9:$C$39,4)=0,"",_xlfn.MAXIFS('1 Daily Report'!$AE$9:$AE$39,'1 Daily Report'!$C$9:$C$39,4)) -> 46319 | P21: =SUMIFS('1 Daily Report'!$D$9:$D$39,'1 Daily Report'!$C$9:$C$39,4) -> 6 | U21: =IF(OR('4 Monthly Review'!$AF$9="",SUMIFS('1 Daily Report'!$D$9:$D$39,'1 Daily Report'!$C$9:$C$39,">0")=0),"",'4 Monthly Review'!$AF$9/SUMIFS('1 Daily Report'!$D$9:$D$39,'1 Daily Report'!$C$9:$C$39,">0")*P21) | AA21: =IF(F21="","",SUMIFS('1 Daily Report'!$AC$9:$AC$39,'1 Daily Report'!$A$9:$A$39,">="&F21,'1 Daily Report'!$A$9:$A$39,"<="&K21)) -> 0 | AG21: =IF(OR(U21="",AA21=""),"",AA21/U21)
B22: Week 5 | F22: =IF(COUNTIF('1 Daily Report'!$C$9:$C$39,5)=0,"",_xlfn.MINIFS('1 Daily Report'!$AE$9:$AE$39,'1 Daily Report'!$C$9:$C$39,5)) -> 46321 | K22: =IF(COUNTIF('1 Daily Report'!$C$9:$C$39,5)=0,"",_xlfn.MAXIFS('1 Daily Report'!$AE$9:$AE$39,'1 Daily Report'!$C$9:$C$39,5)) -> 46326 | P22: =SUMIFS('1 Daily Report'!$D$9:$D$39,'1 Daily Report'!$C$9:$C$39,5) -> 6 | U22: =IF(OR('4 Monthly Review'!$AF$9="",SUMIFS('1 Daily Report'!$D$9:$D$39,'1 Daily Report'!$C$9:$C$39,">0")=0),"",'4 Monthly Review'!$AF$9/SUMIFS('1 Daily Report'!$D$9:$D$39,'1 Daily Report'!$C$9:$C$39,">0")*P22) | AA22: =IF(F22="","",SUMIFS('1 Daily Report'!$AC$9:$AC$39,'1 Daily Report'!$A$9:$A$39,">="&F22,'1 Daily Report'!$A$9:$A$39,"<="&K22)) -> 0 | AG22: =IF(OR(U22="",AA22=""),"",AA22/U22)
B23: Month | F23: =F18 -> 46296 | K23: =EOMONTH('4 Monthly Review'!$X$9,0) -> 46326 | P23: =SUM(P18:P22) -> 27 | U23: =SUM(U18:U22) -> 0 | AA23: =SUM(AA18:AA22) -> 0 | AG23: =IF(N(U23)=0,"",AA23/U23)
B25: HOLIDAYS / NON-WORKING DAYS (type dates; Sundays are excluded automatically)
C28: AGENT PERFORMANCE | N28: Type each agent's monthly target (yellow) · names and previous month in blue
B29: AGENT | H29: MONTHLY TARGET (AED) | M29: ACHIEVED (AED) | R29: ACHIEVEMENT % | V29: GAP (AED) | Z29: REQUIRED / WORKING DAY | AE29: STATUS | AI29: PREVIOUS MONTH (AED)
B30: Alshima | M30: =SUM('1 Daily Report'!$U$9:$U$39) -> 0 | R30: =IF(H30="","",M30/H30) | V30: =IF(H30="","",MAX(0,H30-M30)) | Z30: =IF(OR(H30="",SUMIFS('1 Daily Report'!$D$9:$D$39,'1 Daily Report'!$C$9:$C$39,">0")-SUMIFS('1 Daily Report'!$D$9:$D$39,'1 Daily Report'!$A$9:$A$39,"<="&TODAY())<=0),"",V30/(SUMIFS('1 Daily Report'!$D$9:$D$39,'1 Daily Report'!$C$9:$C$39,">0")-SUMIFS('1 Daily Report'!$D$9:$D$39,'1 Daily Report'!$A$9:$A$39,"<="&TODAY()))) | AE30: =IF(R30="","",IF(R30>=1,"GREEN",IF(R30>=0.7,"YELLOW","RED"))) | AI30: 5850
B31: Chaima | M31: =SUM('1 Daily Report'!$V$9:$V$39) -> 0 | R31: =IF(H31="","",M31/H31) | V31: =IF(H31="","",MAX(0,H31-M31)) | Z31: =IF(OR(H31="",SUMIFS('1 Daily Report'!$D$9:$D$39,'1 Daily Report'!$C$9:$C$39,">0")-SUMIFS('1 Daily Report'!$D$9:$D$39,'1 Daily Report'!$A$9:$A$39,"<="&TODAY())<=0),"",V31/(SUMIFS('1 Daily Report'!$D$9:$D$39,'1 Daily Report'!$C$9:$C$39,">0")-SUMIFS('1 Daily Report'!$D$9:$D$39,'1 Daily Report'!$A$9:$A$39,"<="&TODAY()))) | AE31: =IF(R31="","",IF(R31>=1,"GREEN",IF(R31>=0.7,"YELLOW","RED"))) | AI31: 21530
B32: Harinder | M32: =SUM('1 Daily Report'!$W$9:$W$39) -> 0 | R32: =IF(H32="","",M32/H32) | V32: =IF(H32="","",MAX(0,H32-M32)) | Z32: =IF(OR(H32="",SUMIFS('1 Daily Report'!$D$9:$D$39,'1 Daily Report'!$C$9:$C$39,">0")-SUMIFS('1 Daily Report'!$D$9:$D$39,'1 Daily Report'!$A$9:$A$39,"<="&TODAY())<=0),"",V32/(SUMIFS('1 Daily Report'!$D$9:$D$39,'1 Daily Report'!$C$9:$C$39,">0")-SUMIFS('1 Daily Report'!$D$9:$D$39,'1 Daily Report'!$A$9:$A$39,"<="&TODAY()))) | AE32: =IF(R32="","",IF(R32>=1,"GREEN",IF(R32>=0.7,"YELLOW","RED"))) | AI32: 19654.78
B33: Ibrahim | M33: =SUM('1 Daily Report'!$X$9:$X$39) -> 0 | R33: =IF(H33="","",M33/H33) | V33: =IF(H33="","",MAX(0,H33-M33)) | Z33: =IF(OR(H33="",SUMIFS('1 Daily Report'!$D$9:$D$39,'1 Daily Report'!$C$9:$C$39,">0")-SUMIFS('1 Daily Report'!$D$9:$D$39,'1 Daily Report'!$A$9:$A$39,"<="&TODAY())<=0),"",V33/(SUMIFS('1 Daily Report'!$D$9:$D$39,'1 Daily Report'!$C$9:$C$39,">0")-SUMIFS('1 Daily Report'!$D$9:$D$39,'1 Daily Report'!$A$9:$A$39,"<="&TODAY()))) | AE33: =IF(R33="","",IF(R33>=1,"GREEN",IF(R33>=0.7,"YELLOW","RED"))) | AI33: 23238.59
B34: Khozema | M34: =SUM('1 Daily Report'!$Y$9:$Y$39) -> 0 | R34: =IF(H34="","",M34/H34) | V34: =IF(H34="","",MAX(0,H34-M34)) | Z34: =IF(OR(H34="",SUMIFS('1 Daily Report'!$D$9:$D$39,'1 Daily Report'!$C$9:$C$39,">0")-SUMIFS('1 Daily Report'!$D$9:$D$39,'1 Daily Report'!$A$9:$A$39,"<="&TODAY())<=0),"",V34/(SUMIFS('1 Daily Report'!$D$9:$D$39,'1 Daily Report'!$C$9:$C$39,">0")-SUMIFS('1 Daily Report'!$D$9:$D$39,'1 Daily Report'!$A$9:$A$39,"<="&TODAY()))) | AE34: =IF(R34="","",IF(R34>=1,"GREEN",IF(R34>=0.7,"YELLOW","RED"))) | AI34: 17421
B35: Layan | M35: =SUM('1 Daily Report'!$Z$9:$Z$39) -> 0 | R35: =IF(H35="","",M35/H35) | V35: =IF(H35="","",MAX(0,H35-M35)) | Z35: =IF(OR(H35="",SUMIFS('1 Daily Report'!$D$9:$D$39,'1 Daily Report'!$C$9:$C$39,">0")-SUMIFS('1 Daily Report'!$D$9:$D$39,'1 Daily Report'!$A$9:$A$39,"<="&TODAY())<=0),"",V35/(SUMIFS('1 Daily Report'!$D$9:$D$39,'1 Daily Report'!$C$9:$C$39,">0")-SUMIFS('1 Daily Report'!$D$9:$D$39,'1 Daily Report'!$A$9:$A$39,"<="&TODAY()))) | AE35: =IF(R35="","",IF(R35>=1,"GREEN",IF(R35>=0.7,"YELLOW","RED"))) | AI35: 38161
B36: Rihab | M36: =SUM('1 Daily Report'!$AA$9:$AA$39) -> 0 | R36: =IF(H36="","",M36/H36) | V36: =IF(H36="","",MAX(0,H36-M36)) | Z36: =IF(OR(H36="",SUMIFS('1 Daily Report'!$D$9:$D$39,'1 Daily Report'!$C$9:$C$39,">0")-SUMIFS('1 Daily Report'!$D$9:$D$39,'1 Daily Report'!$A$9:$A$39,"<="&TODAY())<=0),"",V36/(SUMIFS('1 Daily Report'!$D$9:$D$39,'1 Daily Report'!$C$9:$C$39,">0")-SUMIFS('1 Daily Report'!$D$9:$D$39,'1 Daily Report'!$A$9:$A$39,"<="&TODAY()))) | AE36: =IF(R36="","",IF(R36>=1,"GREEN",IF(R36>=0.7,"YELLOW","RED"))) | AI36: 25140
B37: Saha | M37: =SUM('1 Daily Report'!$AB$9:$AB$39) -> 0 | R37: =IF(H37="","",M37/H37) | V37: =IF(H37="","",MAX(0,H37-M37)) | Z37: =IF(OR(H37="",SUMIFS('1 Daily Report'!$D$9:$D$39,'1 Daily Report'!$C$9:$C$39,">0")-SUMIFS('1 Daily Report'!$D$9:$D$39,'1 Daily Report'!$A$9:$A$39,"<="&TODAY())<=0),"",V37/(SUMIFS('1 Daily Report'!$D$9:$D$39,'1 Daily Report'!$C$9:$C$39,">0")-SUMIFS('1 Daily Report'!$D$9:$D$39,'1 Daily Report'!$A$9:$A$39,"<="&TODAY()))) | AE37: =IF(R37="","",IF(R37>=1,"GREEN",IF(R37>=0.7,"YELLOW","RED"))) | AI37: 19342
B38: Team | H38: =SUM(H30:H37) -> 0 | M38: =SUM(M30:M37) -> 0 | R38: =IF(N(H38)=0,"",M38/H38) | V38: =SUM(V30:V37) -> 0 | AI38: =SUM(AI30:AI37) -> 170337.37
B39: GREEN = 100% or more · YELLOW = 70-99% · RED = under 70% (my suggested line). Team target above is a separate business goal and need not equal the sum of agent targets. Previous month = September 2026 as given on 1-Oct-2026.
C42: FORM 4 · SELECT AGENT | L42: Alshima | U42: Pick the agent from the list. The review below fills in from the tables further down.
B45: AGENT NAME | M45: TEAM LEADER | X45: MONTH | AG45: REVIEW DATE
B46: =$L$42 -> Alshima | M46: =$B$9 -> Bindhya TB | X46: =TEXT($X$9,"mmmm yyyy") -> October 2026 | AG46: =IFERROR(IF(INDEX($W$122:$W$129,MATCH($L$42,$B$30:$B$37,0))="","",INDEX($W$122:$W$129,MATCH($L$42,$B$30:$B$37,0))),"")
C48: A · MONTHLY TARGET
C49: 1 | D49: TARGET THIS MONTH | M49: 2 | N49: ACHIEVED | W49: 3 | X49: TARGET HIT? | AG49: 4 | AH49: TARGET NEXT MONTH
C50: =IFERROR(IF(INDEX($H$30:$H$37,MATCH($L$42,$B$30:$B$37,0))="","",INDEX($H$30:$H$37,MATCH($L$42,$B$30:$B$37,0))),"") | M50: =IFERROR(INDEX($M$30:$M$37,MATCH($L$42,$B$30:$B$37,0)),0) -> 0 | W50: =IF(C50="","☐ Yes ☐ No",IF(M50>=C50,"☑ Yes ☐ No","☐ Yes ☑ No")) -> ☐ Yes ☐ No | AG50: =IFERROR(IF(INDEX($G$122:$G$129,MATCH($L$42,$B$30:$B$37,0))="","",INDEX($G$122:$G$129,MATCH($L$42,$B$30:$B$37,0))),"")
B53: 5 | D53: If the target was not hit — main reason | Y53: Tick one
B54: =IFERROR(IF(INDEX($L$122:$L$129,MATCH($L$42,$B$30:$B$37,0))="Low lead volume","☑","☐"),"☐") -> ☐ | C54: Low lead volume | J54: =IFERROR(IF(INDEX($L$122:$L$129,MATCH($L$42,$B$30:$B$37,0))="Low conversion","☑","☐"),"☐") -> ☐ | K54: Low conversion | R54: =IFERROR(IF(INDEX($L$122:$L$129,MATCH($L$42,$B$30:$B$37,0))="Low activity","☑","☐"),"☐") -> ☐ | S54: Low activity | Y54: =IFERROR(IF(INDEX($L$122:$L$129,MATCH($L$42,$B$30:$B$37,0))="Quality issues","☑","☐"),"☐") -> ☐ | Z54: Quality issues | AF54: =IFERROR(IF(INDEX($L$122:$L$129,MATCH($L$42,$B$30:$B$37,0))="Absence / leave","☑","☐"),"☐") -> ☐ | AG54: Absence / leave
B55: =IFERROR(IF(INDEX($L$122:$L$129,MATCH($L$42,$B$30:$B$37,0))="Other","☑","☐"),"☐") -> ☐ | C55: Other: | G55: =IFERROR(IF(INDEX($R$122:$R$129,MATCH($L$42,$B$30:$B$37,0))="","",INDEX($R$122:$R$129,MATCH($L$42,$B$30:$B$37,0))),"")
C57: B · AGENT SKILL CARD | T57: Score each skill from 1 to 10 using the scale below
...
